Workbook

Sheet README
A1: ClaimSense — Project Tracker
A2: Health-insurance claim adjudication · Agentic AI Capstone · Team of 6
A4: WHAT EACH TAB IS FOR
A5: Dashboard | B5: Live progress: per member, per phase, per lecture layer. All formulas — do not type here.
A6: Analysis | B6: High-level analysis: scope, critical path, workload balance, risks.
A7: Team | B7: Fill in member names, emails, backups. Names flow into every other tab.
A8: Master Tasks | B8: Single source of truth: every task with Problem, Date, Status, Owner. Pre-filled with 64 tasks from the capstone brief.
A9: 1-Domain … 6-DevOps | B9: One tab per person: their daily update log (Date, what I did, plan, problem, help needed, hours, evidence).
A10: Problems Log | B10: Every problem/blocker with date raised, owner, days open and resolution. Pre-filled with the open questions from the Discord playbook.
A11: Handoffs | B11: The 9 cross-role handoffs from the playbook, with due dates and status.
A12: Decisions (ADR) | B12: Index of architecture decisions.
A13: Experiments | B13: E1–E4 results in the format the brief requires.
A15: LEGEND
A16: Yellow cells | B16: Input cells — fill these in.
A17: Dropdowns | B17: Status, Owner, Priority, Layer use dropdown lists. Pick from the list so the Dashboard counts correctly.
A18: Status values | B18: Not Started → In Progress → In Review → Done, or Blocked.
A20: TEAM RULES FOR THIS SHEET
A21: Daily | B21: Add one row to your own tab by 10:00 on workdays (same as the #daily-updates rule).
A22: When a task moves | B22: Update Status and % Done in Master Tasks. If blocked, set Blocked, fill Problem + Problem Date, and add a row in Problems Log.
A23: Evidence | B23: Always paste a GitHub issue/PR/doc link. GitHub stays the source of truth; this sheet is the progress view.
A24: Friday | B24: 15-minute review of the Dashboard: overdue tasks, open problems, members with no updates.
A25: Never | B25: No API keys, real claim data or patient details in this sheet.
A27: EXAMPLE ROWS (format to follow)
A28: Daily log row | B28: 2026-10-28 | T09 | Parsed policy PDF into 112 clauses | Add clause metadata + tests | PDF tables break chunking | Open | Tools & Security | 4 | github.com/…/pull/7
A29: Problems Log row | B29: PB-07 | 2026-11-04 | Agents & Orchestration | T26 | L11 Multi-agent | Coverage agent cites wrong clause for ICU | High | Knowledge & Memory | Open | | (auto) | | issue #21
A31: ASSUMPTIONS
A32: Dates | B32: Phase dates assume a ~9-week plan from 26 Oct 2026 to a final review in the week of 21 Dec 2026. The brief does not give the review date — edit the Phase table on the Dashboard and the Due Dates once it is known.
A33: Owners | B33: Task owners follow the six roles in the capstone guide. Reassign any task with the Owner dropdown.

Sheet Dashboard
A1: ClaimSense — Progress Dashboard
A2: All cells are formulas. Update Master Tasks, member tabs and Problems Log; this page updates itself.
A4: Today | B4: =TODAY()
A6: Total tasks | B6: =COUNTA('Master Tasks'!$A$2:$A$400)
A7: Done | B7: =COUNTIF('Master Tasks'!$J$2:$J$400,"Done")
A8: % Done | B8: =IFERROR(B7/B6,0)
A9: In progress / review | B9: =COUNTIF('Master Tasks'!$J$2:$J$400,"In Progress")+COUNTIF('Master Tasks'!$J$2:$J$400,"In Review")
A10: Blocked | B10: =COUNTIF('Master Tasks'!$J$2:$J$400,"Blocked")
A11: Overdue | B11: =COUNTIF('Master Tasks'!$R$2:$R$400,"OVERDUE")
A12: Open problems | B12: =COUNTIFS('Problems Log'!$A$2:$A$300,"<>",'Problems Log'!$I$2:$I$300,"<>Resolved")
A13: Avg % complete (all tasks) | B13: =IFERROR(SUMPRODUCT(('Master Tasks'!$A$2:$A$400<>"")*'Master Tasks'!$K$2:$K$400)/B6,0)
A15: PROGRESS BY MEMBER
A16: Role | B16: Member | C16: Tasks | D16: Done | E16: In Progress / Review | F16: Blocked | G16: Overdue | H16: % Done | I16: Avg % Complete | J16: Open Problems | K16: Hours Logged | L16: Last Log Update | M16: Days Since Update
A17: Domain & Product Lead | B17: =INDEX(Team!$B$5:$B$10,1) | C17: =COUNTIF('Master Tasks'!$F$2:$F$400,A17) | D17: =COUNTIFS('Master Tasks'!$F$2:$F$400,A17,'Master Tasks'!$J$2:$J$400,"Done") | E17: =COUNTIFS('Master Tasks'!$F$2:$F$400,A17,'Master Tasks'!$J$2:$J$400,"In Progress")+COUNTIFS('Master Tasks'!$F$2:$F$400,A17,'Master Tasks'!$J$2:$J$400,"In Review") | F17: =COUNTIFS('Master Tasks'!$F$2:$F$400,A17,'Master Tasks'!$J$2:$J$400,"Blocked") | G17: =COUNTIFS('Master Tasks'!$F$2:$F$400,A17,'Master Tasks'!$R$2:$R$400,"OVERDUE") | H17: =IFERROR(D17/C17,0) | I17: =IFERROR(SUMIF('Master Tasks'!$F$2:$F$400,A17,'Master Tasks'!$K$2:$K$400)/C17,0) | J17: =COUNTIFS('Problems Log'!$H$2:$H$300,A17,'Problems Log'!$I$2:$I$300,"<>Resolved")+COUNTIF('1-Domain'!$F$6:$F$500,"Open") | K17: =SUM('1-Domain'!$H$6:$H$500) | L17: =IF(MAX('1-Domain'!$A$6:$A$500)=0,"No updates",MAX('1-Domain'!$A$6:$A$500)) | M17: =IF(ISNUMBER(L17),TODAY()-L17,"—")
A18: Knowledge & Memory | B18: =INDEX(Team!$B$5:$B$10,2) | C18: =COUNTIF('Master Tasks'!$F$2:$F$400,A18) | D18: =COUNTIFS('Master Tasks'!$F$2:$F$400,A18,'Master Tasks'!$J$2:$J$400,"Done") | E18: =COUNTIFS('Master Tasks'!$F$2:$F$400,A18,'Master Tasks'!$J$2:$J$400,"In Progress")+COUNTIFS('Master Tasks'!$F$2:$F$400,A18,'Master Tasks'!$J$2:$J$400,"In Review") | F18: =COUNTIFS('Master Tasks'!$F$2:$F$400,A18,'Master Tasks'!$J$2:$J$400,"Blocked") | G18: =COUNTIFS('Master Tasks'!$F$2:$F$400,A18,'Master Tasks'!$R$2:$R$400,"OVERDUE") | H18: =IFERROR(D18/C18,0) | I18: =IFERROR(SUMIF('Master Tasks'!$F$2:$F$400,A18,'Master Tasks'!$K$2:$K$400)/C18,0) | J18: =COUNTIFS('Problems Log'!$H$2:$H$300,A18,'Problems Log'!$I$2:$I$300,"<>Resolved")+COUNTIF('2-Knowledge'!$F$6:$F$500,"Open") | K18: =SUM('2-Knowledge'!$H$6:$H$500) | L18: =IF(MAX('2-Knowledge'!$A$6:$A$500)=0,"No updates",MAX('2-Knowledge'!$A$6:$A$500)) | M18: =IF(ISNUMBER(L18),TODAY()-L18,"—")
A19: Agents & Orchestration | B19: =INDEX(Team!$B$5:$B$10,3) | C19: =COUNTIF('Master Tasks'!$F$2:$F$400,A19) | D19: =COUNTIFS('Master Tasks'!$F$2:$F$400,A19,'Master Tasks'!$J$2:$J$400,"Done") | E19: =COUNTIFS('Master Tasks'!$F$2:$F$400,A19,'Master Tasks'!$J$2:$J$400,"In Progress")+COUNTIFS('Master Tasks'!$F$2:$F$400,A19,'Master Tasks'!$J$2:$J$400,"In Review") | F19: =COUNTIFS('Master Tasks'!$F$2:$F$400,A19,'Master Tasks'!$J$2:$J$400,"Blocked") | G19: =COUNTIFS('Master Tasks'!$F$2:$F$400,A19,'Master Tasks'!$R$2:$R$400,"OVERDUE") | H19: =IFERROR(D19/C19,0) | I19: =IFERROR(SUMIF('Master Tasks'!$F$2:$F$400,A19,'Master Tasks'!$K$2:$K$400)/C19,0) | J19: =COUNTIFS('Problems Log'!$H$2:$H$300,A19,'Problems Log'!$I$2:$I$300,"<>Resolved")+COUNTIF('3-Agents'!$F$6:$F$500,"Open") | K19: =SUM('3-Agents'!$H$6:$H$500) | L19: =IF(MAX('3-Agents'!$A$6:$A$500)=0,"No updates",MAX('3-Agents'!$A$6:$A$500)) | M19: =IF(ISNUMBER(L19),TODAY()-L19,"—")
A20: Tools & Security | B20: =INDEX(Team!$B$5:$B$10,4) | C20: =COUNTIF('Master Tasks'!$F$2:$F$400,A20) | D20: =COUNTIFS('Master Tasks'!$F$2:$F$400,A20,'Master Tasks'!$J$2:$J$400,"Done") | E20: =COUNTIFS('Master Tasks'!$F$2:$F$400,A20,'Master Tasks'!$J$2:$J$400,"In Progress")+COUNTIFS('Master Tasks'!$F$2:$F$400,A20,'Master Tasks'!$J$2:$J$400,"In Review") | F20: =COUNTIFS('Master Tasks'!$F$2:$F$400,A20,'Master Tasks'!$J$2:$J$400,"Blocked") | G20: =COUNTIFS('Master Tasks'!$F$2:$F$400,A20,'Master Tasks'!$R$2:$R$400,"OVERDUE") | H20: =IFERROR(D20/C20,0) | I20: =IFERROR(SUMIF('Master Tasks'!$F$2:$F$400,A20,'Master Tasks'!$K$2:$K$400)/C20,0) | J20: =COUNTIFS('Problems Log'!$H$2:$H$300,A20,'Problems Log'!$I$2:$I$300,"<>Resolved")+COUNTIF('4-ToolsSec'!$F$6:$F$500,"Open") | K20: =SUM('4-ToolsSec'!$H$6:$H$500) | L20: =IF(MAX('4-ToolsSec'!$A$6:$A$500)=0,"No updates",MAX('4-ToolsSec'!$A$6:$A$500)) | M20: =IF(ISNUMBER(L20),TODAY()-L20,"—")
A21: Eval & Red-Team | B21: =INDEX(Team!$B$5:$B$10,5) | C21: =COUNTIF('Master Tasks'!$F$2:$F$400,A21) | D21: =COUNTIFS('Master Tasks'!$F$2:$F$400,A21,'Master Tasks'!$J$2:$J$400,"Done") | E21: =COUNTIFS('Master Tasks'!$F$2:$F$400,A21,'Master Tasks'!$J$2:$J$400,"In Progress")+COUNTIFS('Master Tasks'!$F$2:$F$400,A21,'Master Tasks'!$J$2:$J$400,"In Review") | F21: =COUNTIFS('Master Tasks'!$F$2:$F$400,A21,'Master Tasks'!$J$2:$J$400,"Blocked") | G21: =COUNTIFS('Master Tasks'!$F$2:$F$400,A21,'Master Tasks'!$R$2:$R$400,"OVERDUE") | H21: =IFERROR(D21/C21,0) | I21: =IFERROR(SUMIF('Master Tasks'!$F$2:$F$400,A21,'Master Tasks'!$K$2:$K$400)/C21,0) | J21: =COUNTIFS('Problems Log'!$H$2:$H$300,A21,'Problems Log'!$I$2:$I$300,"<>Resolved")+COUNTIF('5-Eval'!$F$6:$F$500,"Open") | K21: =SUM('5-Eval'!$H$6:$H$500) | L21: =IF(MAX('5-Eval'!$A$6:$A$500)=0,"No updates",MAX('5-Eval'!$A$6:$A$500)) | M21: =IF(ISNUMBER(L21),TODAY()-L21,"—")
A22: Deploy & Ops | B22: =INDEX(Team!$B$5:$B$10,6) | C22: =COUNTIF('Master Tasks'!$F$2:$F$400,A22) | D22: =COUNTIFS('Master Tasks'!$F$2:$F$400,A22,'Master Tasks'!$J$2:$J$400,"Done") | E22: =COUNTIFS('Master Tasks'!$F$2:$F$400,A22,'Master Tasks'!$J$2:$J$400,"In Progress")+COUNTIFS('Master Tasks'!$F$2:$F$400,A22,'Master Tasks'!$J$2:$J$400,"In Review") | F22: =COUNTIFS('Master Tasks'!$F$2:$F$400,A22,'Master Tasks'!$J$2:$J$400,"Blocked") | G22: =COUNTIFS('Master Tasks'!$F$2:$F$400,A22,'Master Tasks'!$R$2:$R$400,"OVERDUE") | H22: =IFERROR(D22/C22,0) | I22: =IFERROR(SUMIF('Master Tasks'!$F$2:$F$400,A22,'Master Tasks'!$K$2:$K$400)/C22,0) | J22: =COUNTIFS('Problems Log'!$H$2:$H$300,A22,'Problems Log'!$I$2:$I$300,"<>Resolved")+COUNTIF('6-DevOps'!$F$6:$F$500,"Open") | K22: =SUM('6-DevOps'!$H$6:$H$500) | L22: =IF(MAX('6-DevOps'!$A$6:$A$500)=0,"No updates",MAX('6-DevOps'!$A$6:$A$500)) | M22: =IF(ISNUMBER(L22),TODAY()-L22,"—")
A23: All (team tasks) | B23: Whole team | C23: =COUNTIF('Master Tasks'!$F$2:$F$400,"All") | D23: =COUNTIFS('Master Tasks'!$F$2:$F$400,"All",'Master Tasks'!$J$2:$J$400,"Done") | E23: =COUNTIFS('Master Tasks'!$F$2:$F$400,"All",'Master Tasks'!$J$2:$J$400,"In Progress")+COUNTIFS('Master Tasks'!$F$2:$F$400,"All",'Master Tasks'!$J$2:$J$400,"In Review") | F23: =COUNTIFS('Master Tasks'!$F$2:$F$400,"All",'Master Tasks'!$J$2:$J$400,"Blocked") | G23: =COUNTIFS('Master Tasks'!$F$2:$F$400,"All",'Master Tasks'!$R$2:$R$400,"OVERDUE") | H23: =IFERROR(D23/C23,0) | I23: =IFERROR(SUMIF('Master Tasks'!$F$2:$F$400,"All",'Master Tasks'!$K$2:$K$400)/C23,0)
A25: PROGRESS BY PHASE
A26: Phase | B26: Start | C26: End | D26: Tasks | E26: Done | F26: % Done | G26: Phase Status
A27: P0 Setup & Planning | B27: 46321 | C27: 46325 | D27: =COUNTIF('Master Tasks'!$B$2:$B$400,A27) | E27: =COUNTIFS('Master Tasks'!$B$2:$B$400,A27,'Master Tasks'!$J$2:$J$400,"Done") | F27: =IFERROR(E27/D27,0) | G27: =IF(D27=0,"—",IF(E27=D27,"Complete",IF(TODAY()<B27,"Upcoming",IF(TODAY()>C27,"Behind","Active"))))
A28: P1 Foundations | B28: 46328 | C28: 46339 | D28: =COUNTIF('Master Tasks'!$B$2:$B$400,A28) | E28: =COUNTIFS('Master Tasks'!$B$2:$B$400,A28,'Master Tasks'!$J$2:$J$400,"Done") | F28: =IFERROR(E28/D28,0) | G28: =IF(D28=0,"—",IF(E28=D28,"Complete",IF(TODAY()<B28,"Upcoming",IF(TODAY()>C28,"Behind","Active"))))
A29: P2 Minimum Bar End-to-End | B29: 46342 | C29: 46353 | D29: =COUNTIF('Master Tasks'!$B$2:$B$400,A29) | E29: =COUNTIFS('Master Tasks'!$B$2:$B$400,A29,'Master Tasks'!$J$2:$J$400,"Done") | F29: =IFERROR(E29/D29,0) | G29: =IF(D29=0,"—",IF(E29=D29,"Complete",IF(TODAY()<B29,"Upcoming",IF(TODAY()>C29,"Behind","Active"))))
A30: P3 Signature Challenges + Eval | B30: 46356 | C30: 46367 | D30: =COUNTIF('Master Tasks'!$B$2:$B$400,A30) | E30: =COUNTIFS('Master Tasks'!$B$2:$B$400,A30,'Master Tasks'!$J$2:$J$400,"Done") | F30: =IFERROR(E30/D30,0) | G30: =IF(D30=0,"—",IF(E30=D30,"Complete",IF(TODAY()<B30,"Upcoming",IF(TODAY()>C30,"Behind","Active"))))
A31: P4 Experiments & Report | B31: 46370 | C31: 46374 | D31: =COUNTIF('Master Tasks'!$B$2:$B$400,A31) | E31: =COUNTIFS('Master Tasks'!$B$2:$B$400,A31,'Master Tasks'!$J$2:$J$400,"Done") | F31: =IFERROR(E31/D31,0) | G31: =IF(D31=0,"—",IF(E31=D31,"Complete",IF(TODAY()<B31,"Upcoming",IF(TODAY()>C31,"Behind","Active"))))
A32: P5 Demo & Submission | B32: 46377 | C32: 46380 | D32: =COUNTIF('Master Tasks'!$B$2:$B$400,A32) | E32: =COUNTIFS('Master Tasks'!$B$2:$B$400,A32,'Master Tasks'!$J$2:$J$400,"Done") | F32: =IFERROR(E32/D32,0) | G32: =IF(D32=0,"—",IF(E32=D32,"Complete",IF(TODAY()<B32,"Upcoming",IF(TODAY()>C32,"Behind","Active"))))
A35: MINIMUM-BAR COVERAGE BY LECTURE LAYER
A36: Layer | B36: Tasks | C36: Done | D36: % Done | E36: Blocked
A37: Project Mgmt | B37: =COUNTIF('Master Tasks'!$C$2:$C$400,A37) | C37: =COUNTIFS('Master Tasks'!$C$2:$C$400,A37,'Master Tasks'!$J$2:$J$400,"Done") | D37: =IFERROR(C37/B37,0) | E37: =COUNTIFS('Master Tasks'!$C$2:$C$400,A37,'Master Tasks'!$J$2:$J$400,"Blocked")
A38: Domain/Product | B38: =COUNTIF('Master Tasks'!$C$2:$C$400,A38) | C38: =COUNTIFS('Master Tasks'!$C$2:$C$400,A38,'Master Tasks'!$J$2:$J$400,"Done") | D38: =IFERROR(C38/B38,0) | E38: =COUNTIFS('Master Tasks'!$C$2:$C$400,A38,'Master Tasks'!$J$2:$J$400,"Blocked")
A39: L4–L6 Retrieval | B39: =COUNTIF('Master Tasks'!$C$2:$C$400,A39) | C39: =COUNTIFS('Master Tasks'!$C$2:$C$400,A39,'Master Tasks'!$J$2:$J$400,"Done") | D39: =IFERROR(C39/B39,0) | E39: =COUNTIFS('Master Tasks'!$C$2:$C$400,A39,'Master Tasks'!$J$2:$J$400,"Blocked")
A40: L7 Tools/MCP | B40: =COUNTIF('Master Tasks'!$C$2:$C$400,A40) | C40: =COUNTIFS('Master Tasks'!$C$2:$C$400,A40,'Master Tasks'!$J$2:$J$400,"Done") | D40: =IFERROR(C40/B40,0) | E40: =COUNTIFS('Master Tasks'!$C$2:$C$400,A40,'Master Tasks'!$J$2:$J$400,"Blocked")
A41: L8 Orchestration | B41: =COUNTIF('Master Tasks'!$C$2:$C$400,A41) | C41: =COUNTIFS('Master Tasks'!$C$2:$C$400,A41,'Master Tasks'!$J$2:$J$400,"Done") | D41: =IFERROR(C41/B41,0) | E41: =COUNTIFS('Master Tasks'!$C$2:$C$400,A41,'Master Tasks'!$J$2:$J$400,"Blocked")
A42: L9 Memory | B42: =COUNTIF('Master Tasks'!$C$2:$C$400,A42) | C42: =COUNTIFS('Master Tasks'!$C$2:$C$400,A42,'Master Tasks'!$J$2:$J$400,"Done") | D42: =IFERROR(C42/B42,0) | E42: =COUNTIFS('Master Tasks'!$C$2:$C$400,A42,'Master Tasks'!$J$2:$J$400,"Blocked")
A43: L10 Planning | B43: =COUNTIF('Master Tasks'!$C$2:$C$400,A43) | C43: =COUNTIFS('Master Tasks'!$C$2:$C$400,A43,'Master Tasks'!$J$2:$J$400,"Done") | D43: =IFERROR(C43/B43,0) | E43: =COUNTIFS('Master Tasks'!$C$2:$C$400,A43,'Master Tasks'!$J$2:$J$400,"Blocked")
A44: L11 Multi-agent | B44: =COUNTIF('Master Tasks'!$C$2:$C$400,A44) | C44: =COUNTIFS('Master Tasks'!$C$2:$C$400,A44,'Master Tasks'!$J$2:$J$400,"Done") | D44: =IFERROR(C44/B44,0) | E44: =COUNTIFS('Master Tasks'!$C$2:$C$400,A44,'Master Tasks'!$J$2:$J$400,"Blocked")
A45: L12 Improvement | B45: =COUNTIF('Master Tasks'!$C$2:$C$400,A45) | C45: =COUNTIFS('Master Tasks'!$C$2:$C$400,A45,'Master Tasks'!$J$2:$J$400,"Done") | D45: =IFERROR(C45/B45,0) | E45: =COUNTIFS('Master Tasks'!$C$2:$C$400,A45,'Master Tasks'!$J$2:$J$400,"Blocked")
A46: L13 Evaluation | B46: =COUNTIF('Master Tasks'!$C$2:$C$400,A46) | C46: =COUNTIFS('Master Tasks'!$C$2:$C$400,A46,'Master Tasks'!$J$2:$J$400,"Done") | D46: =IFERROR(C46/B46,0) | E46: =COUNTIFS('Master Tasks'!$C$2:$C$400,A46,'Master Tasks'!$J$2:$J$400,"Blocked")
...

Sheet Analysis
A1: ClaimSense — High-Level Analysis
A2: Built from the capstone guide (16 Oct 2026) and the team Discord playbook (25 Oct 2026).
A4: 1. PROJECT IN BRIEF
A5: Goal | B5: Read a hospitalisation claim, check every bill line against the Arogya Sanjeevani policy wording, compute rupee amounts in code, and prepare a settlement for a claims adjudicator to approve.
A6: User | B6: Claims adjudicator at an insurer or TPA. Today the work is slow, inconsistent, and padded bills are common.
A7: Signature A | B7: Money you can audit — every rupee from unit-tested code, every deduction cites a clause; proportional cut after a room-rent breach done correctly. Owners: Tools & Security (calculator), Agents (coverage analyst).
A8: Signature B | B8: Playbook that learns from adjudicator edits — Reflexion loop on dev claims, human-approved lessons, frozen before held-out run. Owners: Agents (loop), Knowledge (lesson store), Eval (E3).
A9: Marks | B9: Roughly equal: scope & impact · technical depth · presentation · individual viva. Every member must redraw the architecture from memory.
A10: Demo (3 scenes) | B10: (1) Room-rent proportional cut explained line by line. (2) Injected 'pre-approved' note ignored + duplicate bill caught. (3) Edit one line → totals recalc → old approval invalid.
A12: 2. WORKLOAD BALANCE (live from Master Tasks)
A13: Role | B13: Tasks | C13: Critical | D13: High | E13: Share of All Tasks | F13: Comment
A14: Domain & Product Lead | B14: =COUNTIF('Master Tasks'!$F$2:$F$400,A14) | C14: =COUNTIFS('Master Tasks'!$F$2:$F$400,A14,'Master Tasks'!$L$2:$L$400,"Critical") | D14: =COUNTIFS('Master Tasks'!$F$2:$F$400,A14,'Master Tasks'!$L$2:$L$400,"High") | E14: =IFERROR(B14/SUM($B$14:$B$20),0) | F14: Light on code — owns domain content: wording, tariff, synthetic claims, demo, slides.
A15: Knowledge & Memory | B15: =COUNTIF('Master Tasks'!$F$2:$F$400,A15) | C15: =COUNTIFS('Master Tasks'!$F$2:$F$400,A15,'Master Tasks'!$L$2:$L$400,"Critical") | D15: =COUNTIFS('Master Tasks'!$F$2:$F$400,A15,'Master Tasks'!$L$2:$L$400,"High") | E15: =IFERROR(B15/SUM($B$14:$B$20),0) | F15: Front-loaded: retrieval must be ready by mid-Nov for agents.
A16: Agents & Orchestration | B16: =COUNTIF('Master Tasks'!$F$2:$F$400,A16) | C16: =COUNTIFS('Master Tasks'!$F$2:$F$400,A16,'Master Tasks'!$L$2:$L$400,"Critical") | D16: =COUNTIFS('Master Tasks'!$F$2:$F$400,A16,'Master Tasks'!$L$2:$L$400,"High") | E16: =IFERROR(B16/SUM($B$14:$B$20),0) | F16: Heaviest build load and on the critical path; backup should review every PR.
A17: Tools & Security | B17: =COUNTIF('Master Tasks'!$F$2:$F$400,A17) | C17: =COUNTIFS('Master Tasks'!$F$2:$F$400,A17,'Master Tasks'!$L$2:$L$400,"Critical") | D17: =COUNTIFS('Master Tasks'!$F$2:$F$400,A17,'Master Tasks'!$L$2:$L$400,"High") | E17: =IFERROR(B17/SUM($B$14:$B$20),0) | F17: Calculator (Signature A) is the single most important piece of code — start Week 2.
A18: Eval & Red-Team | B18: =COUNTIF('Master Tasks'!$F$2:$F$400,A18) | C18: =COUNTIFS('Master Tasks'!$F$2:$F$400,A18,'Master Tasks'!$L$2:$L$400,"Critical") | D18: =COUNTIFS('Master Tasks'!$F$2:$F$400,A18,'Master Tasks'!$L$2:$L$400,"High") | E18: =IFERROR(B18/SUM($B$14:$B$20),0) | F18: Heaviest in Weeks 6–8 (80 hand worksheets + E1–E4 + report). Start the golden set early.
A19: Deploy & Ops | B19: =COUNTIF('Master Tasks'!$F$2:$F$400,A19) | C19: =COUNTIFS('Master Tasks'!$F$2:$F$400,A19,'Master Tasks'!$L$2:$L$400,"Critical") | D19: =COUNTIFS('Master Tasks'!$F$2:$F$400,A19,'Master Tasks'!$L$2:$L$400,"High") | E19: =IFERROR(B19/SUM($B$14:$B$20),0) | F19: Steady load; Docker + tracing early unblocks everyone.
A20: All | B20: =COUNTIF('Master Tasks'!$F$2:$F$400,A20) | C20: =COUNTIFS('Master Tasks'!$F$2:$F$400,A20,'Master Tasks'!$L$2:$L$400,"Critical") | D20: =COUNTIFS('Master Tasks'!$F$2:$F$400,A20,'Master Tasks'!$L$2:$L$400,"High") | E20: =IFERROR(B20/SUM($B$14:$B$20),0) | F20: Shared tasks: setup, E2E run, contribution review, viva prep.
A22: 3. CRITICAL PATH (if any of these slip, the demo slips)
A23: Step 1 | B23: T06 Policy wording verified → T09 Ingestion → T10 Hybrid index → T16 policy-kb server
A24: Step 2 | B24: T15 Adjudication calculator (parallel, from Week 2) → T26 Coverage analyst
A25: Step 3 | B25: T23 LangGraph graph + T34 Approval gate → T38 First end-to-end run (target 27 Nov)
A26: Step 4 | B26: T22 Golden-set spec → T39 80 expected worksheets → T41 Eval harness → T51–T54 Experiments → T57 Report
A27: Step 5 | B27: T45 Reflexion loop needs a working E2E pipeline AND the harness — it cannot start before ~30 Nov
A29: 4. TOP RISKS
A30: Risk | B30: Likelihood | C30: Impact | D30: Owner | E30: Mitigation | F30: Status
A31: Proportional cut after room-rent breach implemented wrong | B31: Medium | C31: High | D31: Tools & Security | E31: Hand-worked examples from the wording as unit tests before any agent uses the calculator. | F31: Open
A32: 80 hand-made worksheets take far longer than planned | B32: High | C32: High | D32: Eval & Red-Team | E32: Start in P1; Domain Lead drafts cases, Eval computes; spreadsheet template per claim. | F32: Open
A33: Held-out leakage (tuner writes or sees held-out cases) | B33: Medium | C33: High | D33: Eval & Red-Team | E33: Separate folder the agent can't read; Agents role never writes held-out cases; Domain checks them. | F33: Open
A34: Late integration — components don't fit together | B34: Medium | C34: High | D34: Deploy & Ops | E34: Docker Compose + interface handoffs agreed by 13 Nov; E2E run on 27 Nov is a hard milestone. | F34: Open
A35: Ambiguous ownership of L13/L15 | B35: High | C35: Medium | D35: Eval & Red-Team | E35: Close PB-01/PB-02 with ADR-0002 this week. | F35: Open
A36: Health data / keys leak into traces, Discord or this sheet | B36: Low | C36: High | D36: Tools & Security | E36: Synthetic data only; masking in hooks; secret scanning; AutoMod rule. | F36: Open
A37: LLM cost/rate limits during repeated eval runs | B37: Medium | C37: Medium | D37: Deploy & Ops | E37: Cache, fixed small model for specialists, cost per case on dashboard. | F37: Open
A38: Final review date unknown — plan may be too long/short | B38: Medium | C38: Medium | D38: Domain & Product Lead | E38: Confirm date (PB-07) and re-date phases on the Dashboard. | F38: Open
A40: 5. RULES THAT PROTECT THE MARKS
A41: Model proposes, code decides | B41: Arithmetic, eligibility, money and permissions live in tested code. The model picks the clause and explains.
A42: Outside text is data | B42: Discharge summaries, bills and retrieved passages may contain injected instructions.
A43: Exact-payload approval | B43: Approval is tied to the worksheet hash; any edit invalidates it. Two levels above the threshold.
A44: Two separations | B44: Whoever tunes the agent does not write held-out cases; whoever builds defences does not write attacks. Eval & Red-Team owns both.

Sheet Team
A1: Team & Roles
A2: Fill in the yellow cells. Member names appear automatically on every other tab.
A4: Role | B4: Member Name | C4: Backup | D4: Email | E4: Layers | F4: Main Deliverables | G4: GitHub Label | H4: Log Tab
A5: Domain & Product Lead | B5: Member 1 | E5: — | F5: Problem statement, persona, policy wording, tariff table, synthetic claims, held-out check, demo script | G5: area:domain | H5: 1-Domain
A6: Knowledge & Memory | B6: Member 2 | E6: L4–L6, L9 | F6: Ingestion, hybrid retrieval + reranker, claim-history memory, lesson store, memory policy | G6: area:knowledge | H6: 2-Knowledge
A7: Agents & Orchestration | B7: Member 3 | E7: L8, L10–L12 | F7: LangGraph graph, planner, 5 specialist agents, critic loop, Reflexion playbook | G7: area:agents | H7: 3-Agents
A8: Tools & Security | B8: Member 4 | E8: L7, L14, L15 | F8: 4 MCP servers, adjudication calculator, hooks, approval gate, guardrails, threat model | G8: area:tools-security | H8: 4-ToolsSec
A9: Eval & Red-Team | B9: Member 5 | E9: L13 harness, L15 evals | F9: Golden set (80 claims), harness, judge calibration, red-team suite, E1–E4, eval report | G9: area:eval | H9: 5-Eval
A10: Deploy & Ops | B10: Member 6 | E10: L13 CI gate, L16 | F10: FastAPI + UI, Docker Compose, CI eval gate, tracing, Grafana, alerts | G10: area:ops | H10: 6-DevOps
A12: Key links
A13: GitHub repo
A14: Projects board
A15: Discord server
A16: Google Drive folder
A17: Final review date

Sheet Master Tasks
A1: ID | B1: Phase | C1: Layer | D1: Task | E1: Deliverable / Evidence | F1: Owner (Role) | G1: Member | H1: Start Date | I1: Due Date | J1: Status | K1: % Done | L1: Priority | M1: Depends On | N1: Problem / Blocker | O1: Problem Date | P1: Resolution | Q1: Evidence Link | R1: Overdue? | S1: Notes
A2: T01 | B2: P0 Setup & Planning | C2: Project Mgmt | D2: Assign the 6 roles and backups; fill in the Team tab | E2: Team tab complete | F2: All | G2: =IF(F2="","",IF(F2="All","Whole team",IFERROR(INDEX(Team!$B$5:$B$10,MATCH(F2,Team!$A$5:$A$10,0)),""))) | H2: 46321 | I2: 46325 | J2: Not Started | K2: 0 | L2: High | R2: =IF(OR(I2="",J2="Done"),"",IF(I2<TODAY(),"OVERDUE",""))
A3: T02 | B3: P0 Setup & Planning | C3: Project Mgmt | D3: Create GitHub repo, Projects board, area labels, milestones | E3: Repo + board link in Team tab | F3: Deploy & Ops | G3: =IF(F3="","",IF(F3="All","Whole team",IFERROR(INDEX(Team!$B$5:$B$10,MATCH(F3,Team!$A$5:$A$10,0)),""))) | H3: 46321 | I3: 46325 | J3: Not Started | K3: 0 | L3: High | R3: =IF(OR(I3="",J3="Done"),"",IF(I3<TODAY(),"OVERDUE",""))
A4: T03 | B4: P0 Setup & Planning | C4: Project Mgmt | D4: Set up the Discord server per the playbook | E4: Server live, checklist ticked | F4: Deploy & Ops | G4: =IF(F4="","",IF(F4="All","Whole team",IFERROR(INDEX(Team!$B$5:$B$10,MATCH(F4,Team!$A$5:$A$10,0)),""))) | H4: 46321 | I4: 46325 | J4: Not Started | K4: 0 | L4: Medium | R4: =IF(OR(I4="",J4="Done"),"",IF(I4<TODAY(),"OVERDUE",""))
A5: T04 | B5: P0 Setup & Planning | C5: Project Mgmt | D5: Each role writes a one-page plan for its layers | E5: 6 plans linked from issues | F5: All | G5: =IF(F5="","",IF(F5="All","Whole team",IFERROR(INDEX(Team!$B$5:$B$10,MATCH(F5,Team!$A$5:$A$10,0)),""))) | H5: 46321 | I5: 46325 | J5: Not Started | K5: 0 | L5: High | M5: T01 | R5: =IF(OR(I5="",J5="Done"),"",IF(I5<TODAY(),"OVERDUE",""))
A6: T05 | B6: P0 Setup & Planning | C6: L13 Evaluation | D6: ADR: L13/L15 ownership split (Eval vs Deploy, threat-model sign-off) | E6: ADR-0002 accepted | F6: Eval & Red-Team | G6: =IF(F6="","",IF(F6="All","Whole team",IFERROR(INDEX(Team!$B$5:$B$10,MATCH(F6,Team!$A$5:$A$10,0)),""))) | H6: 46321 | I6: 46325 | J6: Not Started | K6: 0 | L6: High | R6: =IF(OR(I6="",J6="Done"),"",IF(I6<TODAY(),"OVERDUE",""))
A7: T06 | B7: P0 Setup & Planning | C7: Domain/Product | D7: Download Arogya Sanjeevani wording (1–2 insurers); verify CIS numbers (room 2%/₹5k, ICU 5%/₹10k, cataract, 5% co-pay, waiting periods) | E7: Wording PDFs + verified rules sheet | F7: Domain & Product Lead | G7: =IF(F7="","",IF(F7="All","Whole team",IFERROR(INDEX(Team!$B$5:$B$10,MATCH(F7,Team!$A$5:$A$10,0)),""))) | H7: 46321 | I7: 46325 | J7: Not Started | K7: 0 | L7: High | R7: =IF(OR(I7="",J7="Done"),"",IF(I7<TODAY(),"OVERDUE",""))
A8: T07 | B8: P0 Setup & Planning | C8: Domain/Product | D8: Write problem statement and claims-adjudicator persona | E8: docs/problem.md | F8: Domain & Product Lead | G8: =IF(F8="","",IF(F8="All","Whole team",IFERROR(INDEX(Team!$B$5:$B$10,MATCH(F8,Team!$A$5:$A$10,0)),""))) | H8: 46321 | I8: 46325 | J8: Not Started | K8: 0 | L8: Medium | R8: =IF(OR(I8="",J8="Done"),"",IF(I8<TODAY(),"OVERDUE",""))
A9: T08 | B9: P0 Setup & Planning | C9: Project Mgmt | D9: Open handoff issues from the Handoffs tab with agreed format + date | E9: 9 handoff issues | F9: All | G9: =IF(F9="","",IF(F9="All","Whole team",IFERROR(INDEX(Team!$B$5:$B$10,MATCH(F9,Team!$A$5:$A$10,0)),""))) | H9: 46321 | I9: 46325 | J9: Not Started | K9: 0 | L9: High | M9: T04 | R9: =IF(OR(I9="",J9="Done"),"",IF(I9<TODAY(),"OVERDUE",""))
A10: T09 | B10: P1 Foundations | C10: L4–L6 Retrieval | D10: Ingestion: policy PDF → one chunk per numbered clause, keep clause no., insurer, date | E10: Ingestion script + chunk sample | F10: Knowledge & Memory | G10: =IF(F10="","",IF(F10="All","Whole team",IFERROR(INDEX(Team!$B$5:$B$10,MATCH(F10,Team!$A$5:$A$10,0)),""))) | H10: 46328 | I10: 46339 | J10: Not Started | K10: 0 | L10: High | M10: T06 | R10: =IF(OR(I10="",J10="Done"),"",IF(I10<TODAY(),"OVERDUE",""))
A11: T10 | B11: P1 Foundations | C11: L4–L6 Retrieval | D11: Hybrid index: BM25 + vectors with RRF, cross-encoder reranker | E11: Index + retrieval API | F11: Knowledge & Memory | G11: =IF(F11="","",IF(F11="All","Whole team",IFERROR(INDEX(Team!$B$5:$B$10,MATCH(F11,Team!$A$5:$A$10,0)),""))) | H11: 46328 | I11: 46339 | J11: Not Started | K11: 0 | L11: High | M11: T09 | R11: =IF(OR(I11="",J11="Done"),"",IF(I11<TODAY(),"OVERDUE",""))
A12: T11 | B12: P1 Foundations | C12: L4–L6 Retrieval | D12: Query rewrite of bill-line terms (e.g. 'OT charges') into policy language | E12: Rewrite module + examples | F12: Knowledge & Memory | G12: =IF(F12="","",IF(F12="All","Whole team",IFERROR(INDEX(Team!$B$5:$B$10,MATCH(F12,Team!$A$5:$A$10,0)),""))) | H12: 46328 | I12: 46339 | J12: Not Started | K12: 0 | L12: Medium | M12: T10 | R12: =IF(OR(I12="",J12="Done"),"",IF(I12<TODAY(),"OVERDUE",""))
A13: T12 | B13: P1 Foundations | C13: L4–L6 Retrieval | D13: Label 30+ retrieval queries; measure Recall@5 baseline | E13: Recall@5 baseline number | F13: Knowledge & Memory | G13: =IF(F13="","",IF(F13="All","Whole team",IFERROR(INDEX(Team!$B$5:$B$10,MATCH(F13,Team!$A$5:$A$10,0)),""))) | H13: 46328 | I13: 46339 | J13: Not Started | K13: 0 | L13: High | M13: T10 | R13: =IF(OR(I13="",J13="Done"),"",IF(I13<TODAY(),"OVERDUE",""))
A14: T13 | B14: P1 Foundations | C14: Domain/Product | D14: Build tariff table: 30 procedures × 3 city tiers | E14: tariff.csv | F14: Domain & Product Lead | G14: =IF(F14="","",IF(F14="All","Whole team",IFERROR(INDEX(Team!$B$5:$B$10,MATCH(F14,Team!$A$5:$A$10,0)),""))) | H14: 46328 | I14: 46339 | J14: Not Started | K14: 0 | L14: High | R14: =IF(OR(I14="",J14="Done"),"",IF(I14<TODAY(),"OVERDUE",""))
A15: T14 | B15: P1 Foundations | C15: Domain/Product | D15: Synthetic claim packet generator + 10 hand-edited packets (no real patient data) | E15: Packets in data/synthetic | F15: Domain & Product Lead | G15: =IF(F15="","",IF(F15="All","Whole team",IFERROR(INDEX(Team!$B$5:$B$10,MATCH(F15,Team!$A$5:$A$10,0)),""))) | H15: 46328 | I15: 46339 | J15: Not Started | K15: 0 | L15: High | M15: T06 | R15: =IF(OR(I15="",J15="Done"),"",IF(I15<TODAY(),"OVERDUE",""))
A16: T15 | B16: P1 Foundations | C16: L7 Tools/MCP | D16: adjudication-calc: room cap, proportional cut, sub-limits, co-pay in plain Python + unit tests | E16: Calculator with passing tests (Signature A) | F16: Tools & Security | G16: =IF(F16="","",IF(F16="All","Whole team",IFERROR(INDEX(Team!$B$5:$B$10,MATCH(F16,Team!$A$5:$A$10,0)),""))) | H16: 46328 | I16: 46339 | J16: Not Started | K16: 0 | L16: Critical | M16: T06 | R16: =IF(OR(I16="",J16="Done"),"",IF(I16<TODAY(),"OVERDUE",""))
A17: T16 | B17: P1 Foundations | C17: L7 Tools/MCP | D17: policy-kb MCP server (search wording, get clause) | E17: Tool schema + 1 test | F17: Tools & Security | G17: =IF(F17="","",IF(F17="All","Whole team",IFERROR(INDEX(Team!$B$5:$B$10,MATCH(F17,Team!$A$5:$A$10,0)),""))) | H17: 46328 | I17: 46339 | J17: Not Started | K17: 0 | L17: High | M17: T10 | R17: =IF(OR(I17="",J17="Done"),"",IF(I17<TODAY(),"OVERDUE",""))
A18: T17 | B18: P1 Foundations | C18: L7 Tools/MCP | D18: tariff MCP server (expected range per procedure + tier) | E18: Tool schema + 1 test | F18: Tools & Security | G18: =IF(F18="","",IF(F18="All","Whole team",IFERROR(INDEX(Team!$B$5:$B$10,MATCH(F18,Team!$A$5:$A$10,0)),""))) | H18: 46328 | I18: 46339 | J18: Not Started | K18: 0 | L18: Medium | M18: T13 | R18: =IF(OR(I18="",J18="Done"),"",IF(I18<TODAY(),"OVERDUE",""))
A19: T18 | B19: P1 Foundations | C19: L7 Tools/MCP | D19: claims-db MCP server + schema (history read; settle_claim write behind gate) | E19: Tool schema + 1 test | F19: Tools & Security | G19: =IF(F19="","",IF(F19="All","Whole team",IFERROR(INDEX(Team!$B$5:$B$10,MATCH(F19,Team!$A$5:$A$10,0)),""))) | H19: 46328 | I19: 46339 | J19: Not Started | K19: 0 | L19: High | R19: =IF(OR(I19="",J19="Done"),"",IF(I19<TODAY(),"OVERDUE",""))
A20: T19 | B20: P1 Foundations | C20: L16 Deployment | D20: Docker Compose skeleton: app, MCP servers, vector store, Prometheus, Grafana | E20: docker compose up works | F20: Deploy & Ops | G20: =IF(F20="","",IF(F20="All","Whole team",IFERROR(INDEX(Team!$B$5:$B$10,MATCH(F20,Team!$A$5:$A$10,0)),""))) | H20: 46328 | I20: 46339 | J20: Not Started | K20: 0 | L20: High | R20: =IF(OR(I20="",J20="Done"),"",IF(I20<TODAY(),"OVERDUE",""))
A21: T20 | B21: P1 Foundations | C21: L16 Deployment | D21: One versioned config for prompts and model IDs | E21: config/ file | F21: Deploy & Ops | G21: =IF(F21="","",IF(F21="All","Whole team",IFERROR(INDEX(Team!$B$5:$B$10,MATCH(F21,Team!$A$5:$A$10,0)),""))) | H21: 46328 | I21: 46339 | J21: Not Started | K21: 0 | L21: Medium | R21: =IF(OR(I21="",J21="Done"),"",IF(I21<TODAY(),"OVERDUE",""))
A22: T21 | B22: P1 Foundations | C22: L13 Evaluation | D22: Tracing (Langfuse/LangSmith) with health data masked | E22: Trace screenshot (masked) | F22: Deploy & Ops | G22: =IF(F22="","",IF(F22="All","Whole team",IFERROR(INDEX(Team!$B$5:$B$10,MATCH(F22,Team!$A$5:$A$10,0)),""))) | H22: 46328 | I22: 46339 | J22: Not Started | K22: 0 | L22: Medium | M22: T19 | R22: =IF(OR(I22="",J22="Done"),"",IF(I22<TODAY(),"OVERDUE",""))
A23: T22 | B23: P1 Foundations | C23: L13 Evaluation | D23: Golden-set spec: 80 claims, case mix, ~20 dev / 60 held-out split | E23: Golden-set plan doc | F23: Eval & Red-Team | G23: =IF(F23="","",IF(F23="All","Whole team",IFERROR(INDEX(Team!$B$5:$B$10,MATCH(F23,Team!$A$5:$A$10,0)),""))) | H23: 46328 | I23: 46339 | J23: Not Started | K23: 0 | L23: High | R23: =IF(OR(I23="",J23="Done"),"",IF(I23<TODAY(),"OVERDUE",""))
A24: T23 | B24: P2 Minimum Bar End-to-End | C24: L8 Orchestration | D24: LangGraph graph: typed state, conditional edges, persistent checkpointer; stop + resume | E24: Graph diagram + resume demo | F24: Agents & Orchestration | G24: =IF(F24="","",IF(F24="All","Whole team",IFERROR(INDEX(Team!$B$5:$B$10,MATCH(F24,Team!$A$5:$A$10,0)),""))) | H24: 46342 | I24: 46353 | J24: Not Started | K24: 0 | L24: Critical | R24: =IF(OR(I24="",J24="Done"),"",IF(I24<TODAY(),"OVERDUE",""))
A25: T24 | B25: P2 Minimum Bar End-to-End | C25: L10 Planning | D25: Planner: show plan object; replan when a tool result contradicts it | E25: Trace showing a replan | F25: Agents & Orchestration | G25: =IF(F25="","",IF(F25="All","Whole team",IFERROR(INDEX(Team!$B$5:$B$10,MATCH(F25,Team!$A$5:$A$10,0)),""))) | H25: 46342 | I25: 46353 | J25: Not Started | K25: 0 | L25: High | M25: T23 | R25: =IF(OR(I25="",J25="Done"),"",IF(I25<TODAY(),"OVERDUE",""))
A26: T25 | B26: P2 Minimum Bar End-to-End | C26: L11 Multi-agent | D26: Extraction agent: typed fields + every bill line with source spans | E26: Extraction output on 10 packets | F26: Agents & Orchestration | G26: =IF(F26="","",IF(F26="All","Whole team",IFERROR(INDEX(Team!$B$5:$B$10,MATCH(F26,Team!$A$5:$A$10,0)),""))) | H26: 46342 | I26: 46353 | J26: Not Started | K26: 0 | L26: High | M26: T14 | R26: =IF(OR(I26="",J26="Done"),"",IF(I26<TODAY(),"OVERDUE",""))
A27: T26 | B27: P2 Minimum Bar End-to-End | C27: L11 Multi-agent | D27: Coverage analyst: clause per line, calls calculator (model picks clause, code computes ₹) | E27: Worksheet output | F27: Agents & Orchestration | G27: =IF(F27="","",IF(F27="All","Whole team",IFERROR(INDEX(Team!$B$5:$B$10,MATCH(F27,Team!$A$5:$A$10,0)),""))) | H27: 46342 | I27: 46353 | J27: Not Started | K27: 0 | L27: Critical | M27: T15,T16 | R27: =IF(OR(I27="",J27="Done"),"",IF(I27<TODAY(),"OVERDUE",""))
A28: T27 | B28: P2 Minimum Bar End-to-End | C28: L11 Multi-agent | D28: Fraud analyst: duplicates, tariff outliers, date checks | E28: Fraud flags on test packets | F28: Agents & Orchestration | G28: =IF(F28="","",IF(F28="All","Whole team",IFERROR(INDEX(Team!$B$5:$B$10,MATCH(F28,Team!$A$5:$A$10,0)),""))) | H28: 46342 | I28: 46353 | J28: Not Started | K28: 0 | L28: Medium | M28: T17,T18 | R28: =IF(OR(I28="",J28="Done"),"",IF(I28<TODAY(),"OVERDUE",""))
A29: T28 | B29: P2 Minimum Bar End-to-End | C29: L11 Multi-agent | D29: Critic agent + one-revision loop (re-run calc, check citations) | E29: Critic rejection trace | F29: Agents & Orchestration | G29: =IF(F29="","",IF(F29="All","Whole team",IFERROR(INDEX(Team!$B$5:$B$10,MATCH(F29,Team!$A$5:$A$10,0)),""))) | H29: 46342 | I29: 46353 | J29: Not Started | K29: 0 | L29: High | M29: T26 | R29: =IF(OR(I29="",J29="Done"),"",IF(I29<TODAY(),"OVERDUE",""))
A30: T29 | B30: P2 Minimum Bar End-to-End | C30: L11 Multi-agent | D30: Settlement agent + letter with reason per deduction | E30: Sample letter | F30: Agents & Orchestration | G30: =IF(F30="","",IF(F30="All","Whole team",IFERROR(INDEX(Team!$B$5:$B$10,MATCH(F30,Team!$A$5:$A$10,0)),""))) | H30: 46342 | I30: 46353 | J30: Not Started | K30: 0 | L30: Medium | M30: T34 | R30: =IF(OR(I30="",J30="Done"),"",IF(I30<TODAY(),"OVERDUE",""))
A31: T30 | B31: P2 Minimum Bar End-to-End | C31: L11 Multi-agent | D31: Single-agent baseline with same tools and budget | E31: Baseline runnable | F31: Agents & Orchestration | G31: =IF(F31="","",IF(F31="All","Whole team",IFERROR(INDEX(Team!$B$5:$B$10,MATCH(F31,Team!$A$5:$A$10,0)),""))) | H31: 46342 | I31: 46353 | J31: Not Started | K31: 0 | L31: High | M31: T26 | R31: =IF(OR(I31="",J31="Done"),"",IF(I31<TODAY(),"OVERDUE",""))
A32: T31 | B32: P2 Minimum Bar End-to-End | C32: L9 Memory | D32: Claim history per policy (sub-limits used, bills seen) + memory policy page | E32: Memory policy (1 page) | F32: Knowledge & Memory | G32: =IF(F32="","",IF(F32="All","Whole team",IFERROR(INDEX(Team!$B$5:$B$10,MATCH(F32,Team!$A$5:$A$10,0)),""))) | H32: 46342 | I32: 46353 | J32: Not Started | K32: 0 | L32: High | M32: T18 | R32: =IF(OR(I32="",J32="Done"),"",IF(I32<TODAY(),"OVERDUE",""))
A33: T32 | B33: P2 Minimum Bar End-to-End | C33: L9 Memory | D33: Short-term context trimming/summarising | E33: Config + test | F33: Knowledge & Memory | G33: =IF(F33="","",IF(F33="All","Whole team",IFERROR(INDEX(Team!$B$5:$B$10,MATCH(F33,Team!$A$5:$A$10,0)),""))) | H33: 46342 | I33: 46353 | J33: Not Started | K33: 0 | L33: Medium | M33: T23 | R33: =IF(OR(I33="",J33="Done"),"",IF(I33<TODAY(),"OVERDUE",""))
A34: T33 | B34: P2 Minimum Bar End-to-End | C34: L14 Human control | D34: Hooks: pre-tool permission + budget; post-tool log + scrub | E34: Hook tests | F34: Tools & Security | G34: =IF(F34="","",IF(F34="All","Whole team",IFERROR(INDEX(Team!$B$5:$B$10,MATCH(F34,Team!$A$5:$A$10,0)),""))) | H34: 46342 | I34: 46353 | J34: Not Started | K34: 0 | L34: High | R34: =IF(OR(I34="",J34="Done"),"",IF(I34<TODAY(),"OVERDUE",""))
A35: T34 | B35: P2 Minimum Bar End-to-End | C35: L14 Human control | D35: Approval gate: interrupt() tied to worksheet hash; 2 levels above threshold | E35: Edit-invalidates-approval demo | F35: Tools & Security | G35: =IF(F35="","",IF(F35="All","Whole team",IFERROR(INDEX(Team!$B$5:$B$10,MATCH(F35,Team!$A$5:$A$10,0)),""))) | H35: 46342 | I35: 46353 | J35: Not Started | K35: 0 | L35: Critical | M35: T23 | R35: =IF(OR(I35="",J35="Done"),"",IF(I35<TODAY(),"OVERDUE",""))
A36: T35 | B36: P2 Minimum Bar End-to-End | C36: L15 Security | D36: Input guardrails: mask health data, injection check, documents as data | E36: Guardrail tests | F36: Tools & Security | G36: =IF(F36="","",IF(F36="All","Whole team",IFERROR(INDEX(Team!$B$5:$B$10,MATCH(F36,Team!$A$5:$A$10,0)),""))) | H36: 46342 | I36: 46353 | J36: Not Started | K36: 0 | L36: High | R36: =IF(OR(I36="",J36="Done"),"",IF(I36<TODAY(),"OVERDUE",""))
A37: T36 | B37: P2 Minimum Bar End-to-End | C37: L15 Security | D37: Output guardrails: deductions cited, totals add up, right patient/policy no. | E37: Guardrail tests | F37: Tools & Security | G37: =IF(F37="","",IF(F37="All","Whole team",IFERROR(INDEX(Team!$B$5:$B$10,MATCH(F37,Team!$A$5:$A$10,0)),""))) | H37: 46342 | I37: 46353 | J37: Not Started | K37: 0 | L37: High | R37: =IF(OR(I37="",J37="Done"),"",IF(I37<TODAY(),"OVERDUE",""))
A38: T37 | B38: P2 Minimum Bar End-to-End | C38: L16 Deployment | D38: FastAPI with streaming + case UI (upload packet, view worksheet, approve/edit) | E38: UI demo | F38: Deploy & Ops | G38: =IF(F38="","",IF(F38="All","Whole team",IFERROR(INDEX(Team!$B$5:$B$10,MATCH(F38,Team!$A$5:$A$10,0)),""))) | H38: 46342 | I38: 46353 | J38: Not Started | K38: 0 | L38: High | M38: T19 | R38: =IF(OR(I38="",J38="Done"),"",IF(I38<TODAY(),"OVERDUE",""))
A39: T38 | B39: P2 Minimum Bar End-to-End | C39: Project Mgmt | D39: First end-to-end run on 5 dev claims | E39: E2E trace | F39: All | G39: =IF(F39="","",IF(F39="All","Whole team",IFERROR(INDEX(Team!$B$5:$B$10,MATCH(F39,Team!$A$5:$A$10,0)),""))) | H39: 46342 | I39: 46353 | J39: Not Started | K39: 0 | L39: Critical | M39: T23,T37 | R39: =IF(OR(I39="",J39="Done"),"",IF(I39<TODAY(),"OVERDUE",""))
A40: T39 | B40: P3 Signature Challenges + Eval | C40: L13 Evaluation | D40: Hand-calculate expected worksheets for 80 claims (room-rent breach, waiting period, duplicates, consumables, partial sub-limits, out-of-period) | E40: Expected worksheets | F40: Eval & Red-Team | G40: =IF(F40="","",IF(F40="All","Whole team",IFERROR(INDEX(Team!$B$5:$B$10,MATCH(F40,Team!$A$5:$A$10,0)),""))) | H40: 46356 | I40: 46367 | J40: Not Started | K40: 0 | L40: Critical | M40: T22 | R40: =IF(OR(I40="",J40="Done"),"",IF(I40<TODAY(),"OVERDUE",""))
...

Sheet 1-Domain
A1: ="Daily Log — "&IFERROR(INDEX(Team!$B$5:$B$10,1),"")&" (Domain & Product Lead)"
A2: Layers: — · Problem statement, persona, policy wording, tariff table, synthetic claims, held-out check, demo script
A3: Updates logged: | B3: =COUNT(A6:A500) | C3: Open problems: | D3: =COUNTIF(F6:F500,"Open") | E3: Hours logged: | F3: =SUM(H6:H500) | G3: My open tasks: | H3: =COUNTIFS('Master Tasks'!$F$2:$F$400,"Domain & Product Lead",'Master Tasks'!$J$2:$J$400,"<>Done")
A5: Date | B5: Task ID | C5: What I Did | D5: Plan Next | E5: Problem / Blocker | F5: Problem Status | G5: Help Needed From | H5: Hours | I5: Evidence Link (PR / Issue / Doc) | J5: Handoff Others Are Waiting On

Sheet 2-Knowledge
A1: ="Daily Log — "&IFERROR(INDEX(Team!$B$5:$B$10,2),"")&" (Knowledge & Memory)"
A2: Layers: L4–L6, L9 · Ingestion, hybrid retrieval + reranker, claim-history memory, lesson store, memory policy
A3: Updates logged: | B3: =COUNT(A6:A500) | C3: Open problems: | D3: =COUNTIF(F6:F500,"Open") | E3: Hours logged: | F3: =SUM(H6:H500) | G3: My open tasks: | H3: =COUNTIFS('Master Tasks'!$F$2:$F$400,"Knowledge & Memory",'Master Tasks'!$J$2:$J$400,"<>Done")
A5: Date | B5: Task ID | C5: What I Did | D5: Plan Next | E5: Problem / Blocker | F5: Problem Status | G5: Help Needed From | H5: Hours | I5: Evidence Link (PR / Issue / Doc) | J5: Handoff Others Are Waiting On

Sheet 3-Agents
A1: ="Daily Log — "&IFERROR(INDEX(Team!$B$5:$B$10,3),"")&" (Agents & Orchestration)"
A2: Layers: L8, L10–L12 · LangGraph graph, planner, 5 specialist agents, critic loop, Reflexion playbook
A3: Updates logged: | B3: =COUNT(A6:A500) | C3: Open problems: | D3: =COUNTIF(F6:F500,"Open") | E3: Hours logged: | F3: =SUM(H6:H500) | G3: My open tasks: | H3: =COUNTIFS('Master Tasks'!$F$2:$F$400,"Agents & Orchestration",'Master Tasks'!$J$2:$J$400,"<>Done")
A5: Date | B5: Task ID | C5: What I Did | D5: Plan Next | E5: Problem / Blocker | F5: Problem Status | G5: Help Needed From | H5: Hours | I5: Evidence Link (PR / Issue / Doc) | J5: Handoff Others Are Waiting On

Sheet 4-ToolsSec
A1: ="Daily Log — "&IFERROR(INDEX(Team!$B$5:$B$10,4),"")&" (Tools & Security)"
A2: Layers: L7, L14, L15 · 4 MCP servers, adjudication calculator, hooks, approval gate, guardrails, threat model
A3: Updates logged: | B3: =COUNT(A6:A500) | C3: Open problems: | D3: =COUNTIF(F6:F500,"Open") | E3: Hours logged: | F3: =SUM(H6:H500) | G3: My open tasks: | H3: =COUNTIFS('Master Tasks'!$F$2:$F$400,"Tools & Security",'Master Tasks'!$J$2:$J$400,"<>Done")
A5: Date | B5: Task ID | C5: What I Did | D5: Plan Next | E5: Problem / Blocker | F5: Problem Status | G5: Help Needed From | H5: Hours | I5: Evidence Link (PR / Issue / Doc) | J5: Handoff Others Are Waiting On

Sheet 5-Eval
A1: ="Daily Log — "&IFERROR(INDEX(Team!$B$5:$B$10,5),"")&" (Eval & Red-Team)"
A2: Layers: L13 harness, L15 evals · Golden set (80 claims), harness, judge calibration, red-team suite, E1–E4, eval report
A3: Updates logged: | B3: =COUNT(A6:A500) | C3: Open problems: | D3: =COUNTIF(F6:F500,"Open") | E3: Hours logged: | F3: =SUM(H6:H500) | G3: My open tasks: | H3: =COUNTIFS('Master Tasks'!$F$2:$F$400,"Eval & Red-Team",'Master Tasks'!$J$2:$J$400,"<>Done")
A5: Date | B5: Task ID | C5: What I Did | D5: Plan Next | E5: Problem / Blocker | F5: Problem Status | G5: Help Needed From | H5: Hours | I5: Evidence Link (PR / Issue / Doc) | J5: Handoff Others Are Waiting On

Sheet 6-DevOps
A1: ="Daily Log — "&IFERROR(INDEX(Team!$B$5:$B$10,6),"")&" (Deploy & Ops)"
A2: Layers: L13 CI gate, L16 · FastAPI + UI, Docker Compose, CI eval gate, tracing, Grafana, alerts
A3: Updates logged: | B3: =COUNT(A6:A500) | C3: Open problems: | D3: =COUNTIF(F6:F500,"Open") | E3: Hours logged: | F3: =SUM(H6:H500) | G3: My open tasks: | H3: =COUNTIFS('Master Tasks'!$F$2:$F$400,"Deploy & Ops",'Master Tasks'!$J$2:$J$400,"<>Done")
A5: Date | B5: Task ID | C5: What I Did | D5: Plan Next | E5: Problem / Blocker | F5: Problem Status | G5: Help Needed From | H5: Hours | I5: Evidence Link (PR / Issue / Doc) | J5: Handoff Others Are Waiting On

Sheet Problems Log
A1: ID | B1: Date Raised | C1: Raised By | D1: Task ID | E1: Layer | F1: Problem | G1: Impact | H1: Assigned To | I1: Status | J1: Date Resolved | K1: Days Open | L1: Resolution | M1: Link
A2: PB-01 | B2: 46320 | C2: Domain & Product Lead | D2: T05 | E2: L13 Evaluation | F2: L13 is listed under two roles. Confirm split: Eval owns harness + metrics, Deploy owns CI gate + dashboards. | G2: High | H2: Eval & Red-Team | I2: Open | K2: =IF(B2="","",IF(J2="",TODAY()-B2,J2-B2))
A3: PB-02 | B3: 46320 | C3: Domain & Product Lead | D3: T05 | E3: L15 Security | F3: L15 is shared between Tools/Security (guardrails) and Eval (security evals). Who signs off the threat model? | G3: High | H3: Tools & Security | I3: Open | K3: =IF(B3="","",IF(J3="",TODAY()-B3,J3-B3))
A4: PB-03 | B4: 46320 | C4: Domain & Product Lead | E4: Project Mgmt | F4: Who are the mentors and the domain expert, and how often will they join? | G4: Medium | H4: Domain & Product Lead | I4: Open | K4: =IF(B4="","",IF(J4="",TODAY()-B4,J4-B4))
A5: PB-04 | B5: 46320 | C5: Domain & Product Lead | E5: Project Mgmt | F5: Do the brief or university require data-handling / privacy rules for Discord and shared docs? | G5: Medium | H5: Domain & Product Lead | I5: Open | K5: =IF(B5="","",IF(J5="",TODAY()-B5,J5-B5))
A6: PB-05 | B6: 46320 | C6: Domain & Product Lead | D6: T64 | E6: Project Mgmt | F6: Are grades based on individual contribution evidence? What format does the course expect? | G6: High | H6: Domain & Product Lead | I6: Open | K6: =IF(B6="","",IF(J6="",TODAY()-B6,J6-B6))
A7: PB-06 | B7: 46320 | C7: Domain & Product Lead | E7: Project Mgmt | F7: Which tools beyond GitHub are approved (Google Drive/Sheets, Notion, Excalidraw)? | G7: Low | H7: Domain & Product Lead | I7: Open | K7: =IF(B7="","",IF(J7="",TODAY()-B7,J7-B7))
A8: PB-07 | B8: 46320 | C8: Domain & Product Lead | E8: Project Mgmt | F8: Final review / demo date not in the brief — needed to fix the phase plan. | G8: High | H8: Domain & Product Lead | I8: Open | K8: =IF(B8="","",IF(J8="",TODAY()-B8,J8-B8))
K9: =IF(B9="","",IF(J9="",TODAY()-B9,J9-B9))
K10: =IF(B10="","",IF(J10="",TODAY()-B10,J10-B10))
K11: =IF(B11="","",IF(J11="",TODAY()-B11,J11-B11))
K12: =IF(B12="","",IF(J12="",TODAY()-B12,J12-B12))
K13: =IF(B13="","",IF(J13="",TODAY()-B13,J13-B13))
K14: =IF(B14="","",IF(J14="",TODAY()-B14,J14-B14))
K15: =IF(B15="","",IF(J15="",TODAY()-B15,J15-B15))
K16: =IF(B16="","",IF(J16="",TODAY()-B16,J16-B16))
K17: =IF(B17="","",IF(J17="",TODAY()-B17,J17-B17))
K18: =IF(B18="","",IF(J18="",TODAY()-B18,J18-B18))
K19: =IF(B19="","",IF(J19="",TODAY()-B19,J19-B19))
K20: =IF(B20="","",IF(J20="",TODAY()-B20,J20-B20))
... K300: =IF(B300="","",IF(J300="",TODAY()-B300,J300-B300))

Sheet Handoffs
A1: # | B1: From | C1: To | D1: What Is Handed Over | E1: Needed Before | F1: Due Date | G1: Status | H1: GitHub Issue | I1: Notes
A2: 1 | B2: Domain & Product Lead | C2: Knowledge & Memory | D2: Policy documents and source corpus, with permitted-use notes | E2: Ingestion work starts | F2: 46328 | G2: Not Started
A3: 2 | B3: Domain & Product Lead | C3: Eval & Red-Team | D3: Golden-set cases and expected answers | E3: The first eval run | F3: 46353 | G3: Not Started
A4: 3 | B4: Knowledge & Memory | C4: Agents & Orchestration | D4: Retrieval and memory interface (signatures, return format) | E4: Specialist agents call retrieval | F4: 46339 | G4: Not Started
A5: 4 | B5: Tools & Security | C5: Agents & Orchestration | D5: MCP tool contracts, approval-gate hooks, guardrail API | E5: Agents use tools | F5: 46339 | G5: Not Started
A6: 5 | B6: Agents & Orchestration | C6: Eval & Red-Team | D6: Runnable graph entry point and trace output | E6: End-to-end evals | F6: 46353 | G6: Not Started
A7: 6 | B7: Eval & Red-Team | C7: Deploy & Ops | D7: Eval CLI, metrics and pass thresholds | E7: The CI eval gate | F7: 46360 | G7: Not Started
A8: 7 | B8: Eval & Red-Team | C8: Tools & Security | D8: Red-team findings (via #security-private) | E8: Each guardrail iteration | F8: 46367 | G8: Not Started
A9: 8 | B9: Deploy & Ops | C9: All | D9: Docker Compose dev environment, tracing setup | E9: Week 2 integration | F9: 46332 | G9: Not Started
A10: 9 | B10: All | C10: Domain & Product Lead | D10: Demo-ready features and known limitations | E10: Demo rehearsal | F10: 46374 | G10: Not Started

Sheet Decisions (ADR)
A1: ADR # | B1: Date | C1: Title | D1: Owner | E1: Layers | F1: Status | G1: Link (docs/adr/…) | H1: Roles That Must Act
A2: ADR-0001 | B2: 46324 | C2: Overall architecture (follow the reference architecture, Figure 3) | D2: Agents & Orchestration | E2: All | F2: Proposed
A3: ADR-0002 | B3: 46324 | C3: L13/L15 ownership split | D3: Eval & Red-Team | E3: L13, L15 | F3: Proposed

Sheet Experiments
A1: Exp | B1: Question | C1: Configuration | D1: Run Date | E1: Task Success (n/N) | F1: Policy Violations | G1: Attack Success | H1: False Blocks | I1: Cost / Case (₹ or $) | J1: Latency p50 (s) | K1: Latency p95 (s) | L1: Errors / Timeouts | M1: Repeat # | N1: Owner | O1: Link
A2: E1 | B2: Does the agent justify its cost? | C2: C0 fixed workflow | N2: Eval & Red-Team
A3: E1 | C3: C1 single agent | N3: Eval & Red-Team
A4: E1 | C4: C2 agent team | N4: Eval & Red-Team
A5: E2 | B5: Do the defences work? | C5: Defences OFF | N5: Eval & Red-Team
A6: E2 | C6: Defences ON | N6: Eval & Red-Team
A7: E3 | B7: Did the lessons help? (repeat ×3) | C7: Held-out, no playbook | N7: Eval & Red-Team
A8: E3 | C8: Held-out, with playbook | N8: Eval & Red-Team
A9: E4 | B9: LLM arithmetic vs calculator (₹ error) | C9: LLM computes amounts | N9: Eval & Red-Team
A10: E4 | C10: Calculator computes amounts | N10: Eval & Red-Team
A11: Mem | B11: Memory on vs off | C11: Memory OFF | N11: Knowledge & Memory
A12: Mem | C12: Memory ON | N12: Knowledge & Memory
A13: Ret | B13: Recall@5 before/after one change | C13: Baseline | N13: Knowledge & Memory
A14: Ret | C14: After change | N14: Knowledge & Memory
A17: Report every configuration, including failed and timed-out runs. Repeat the final held-out comparison 3 times and report the spread (capstone guide, p.6).
